Workbook

Sheet Raw
A1: XML 24 R3.htm IDEA: XBRL DOCUMENT
A2: CONSOLIDATED STATEMENTS OF INCOME - USD ()
A3: shares in Millions, in Millions
A4: 12 Months Ended
A5: Dec. 31, 2025
A6: Dec. 31, 2024
A7: Dec. 31, 2023 | B7: Dec. 31, 2023 | C7: Dec. 31, 2024 | D7: Dec. 31, 2025
A8: Net Operating Revenues | B8: 45754 | C8: 47061 | D8: 47941
A9: Cost of goods sold | B9: 18520 | C9: 18324 | D9: 18397
A10: Gross Profit | B10: 27234 | C10: 28737 | D10: 29544
A11: Selling, general and administrative expenses | B11: 13972 | C11: 14582 | D11: 14521
A12: Other operating charges | B12: 1951 | C12: 4163 | D12: 1261
A13: Operating Income | B13: 11311 | C13: 9992 | D13: 13762
A14: Interest income | B14: 907 | C14: 988 | D14: 786
A15: Interest expense | B15: 1527 | C15: 1656 | D15: 1654
A16: Equity income (loss) — net | B16: 1691 | C16: 1770 | D16: 2031
A17: Other income (loss) — net | B17: 570 | C17: 1992 | D17: 1073
A18: Income Before Income Taxes | B18: 12952 | C18: 13086 | D18: 15998
A19: Income taxes | B19: 2249 | C19: 2437 | D19: 2861
... A27: Average Shares Outstanding — Diluted | B27: 4339 | C27: 4320 | D27: 4313
A31: XML 28 R7.htm IDEA: XBRL DOCUMENT
A32: CONSOLIDATED STATEMENTS OF CASH FLOWS - USD ($) | B32: 12 Months Ended
A33: $ in Millions
B34: Dec. 31, 2023 | C34: Dec. 31, 2024 | D34: Dec. 31, 2025
A35: OPERATING ACTIVITIES
A36: Consolidated Net Income | B36: 10703 | C36: 10649 | D36: 13137
A37: Depreciation and amortization | B37: 1128 | C37: 1075 | D37: 1050
A38: Stock-based compensation expense | B38: 254 | C38: 286 | D38: 279
A39: Deferred income taxes | B39: -2 | C39: -11 | D39: 517
A40: Equity (income) loss — net of dividends | B40: -1019 | C40: -802 | D40: -1038
A41: Foreign currency adjustments | B41: 175 | C41: -110 | D41: 191
A42: Significant (gains) losses — net | B42: -492 | C42: -1737 | D42: -713
A43: Other operating charges | B43: 1741 | C43: 4000 | D43: 1052
A44: Other items | B44: -43 | C44: -311 | D44: 141
A45: Net change in operating assets and liabilities | B45: -846 | C45: -6234 | D45: -7208
A46: Net Cash Provided by Operating Activities | B46: 11599 | C46: 6805 | D46: 7408
A47: INVESTING ACTIVITIES
A48: Purchases of investments | B48: -6698 | C48: -5640 | D48: -6160
A49: Proceeds from disposals of investments | B49: 4354 | C49: 6589 | D49: 4665
A50: Acquisitions of businesses, equity method investments and nonmarketable securities | B50: -62 | C50: -315 | D50: -461
...

Sheet IS
B1: The Coca-Cola Company (NYSE: KO)
B2: Income Statement
B3: ($ in millions, except per share data)
B5: Fiscal Year Ending December 31, | D5: 2021 | E5: =D5+1 -> 2022 | F5: =E5+1 -> 2023 | G5: =F5+1 -> 2024 | H5: =G5+1 -> 2025
B6: Net operating revenues | F6: 45754 | G6: 47061 | H6: 47941
B7: % growth | G7: =G6/F6-1 -> 0.028565808 | H7: =H6/G6-1 -> 0.018699135
B8: Cost of goods sold | F8: 18520 | G8: 18324 | H8: 18397
B9: Gross profit | F9: =F6-F8 -> 27234 | G9: =G6-G8 -> 28737 | H9: =H6-H8 -> 29544
B10: % margin | F10: =F9/F6 -> 0.59522665 | G10: =G9/G6 -> 0.61063301 | H10: =H9/H6 -> 0.61625748
B11: Selling, general & administrative expenses | F11: 13972 | G11: 14582 | H11: 14521
B12: % of revenue | F12: =F11/F6 -> 0.30537221 | G12: =G11/G6 -> 0.30985317 | H12: =H11/H6 -> 0.30289314
B13: Other operating charges | F13: 1951 | G13: 4163 | H13: 1261
B14: Operating income | F14: =F9-F11-F13 -> 11311 | G14: =G9-G11-G13 -> 9992 | H14: =H9-H11-H13 -> 13762
B15: % margin | F15: =F14/F6 -> 0.24721336 | G15: =G14/G6 -> 0.21232018 | H15: =H14/H6 -> 0.28706118
B16: Interest income | F16: 907 | G16: 988 | H16: 786
B17: Interest expense | F17: 1527 | G17: 1656 | H17: 1654
B18: Equity income (loss) – net | F18: 1691 | G18: 1770 | H18: 2031
B19: Other income (loss) – net | F19: 570 | G19: 1992 | H19: 1073
B20: Income before income taxes | F20: =F14+F16-F17+F18+F19 -> 12952 | G20: =G14+G16-G17+G18+G19 -> 13086 | H20: =H14+H16-H17+H18+H19 -> 15998
B21: Income taxes | F21: 2249 | G21: 2437 | H21: 2861
B22: Effective tax rate | F22: =F21/F20 -> 0.17364114 | G22: =G21/G20 -> 0.18622956 | H22: =H21/H20 -> 0.17883485
B23: Consolidated net income | F23: =F20-F21 -> 10703 | G23: =G20-G21 -> 10649 | H23: =H20-H21 -> 13137
B24: Less: Net income attributable to NCI | F24: -11 | G24: 18 | H24: 30
B25: Net income attributable to KO | F25: =F23-F24 -> 10714 | G25: =G23-G24 -> 10631 | H25: =H23-H24 -> 13107
B26: % margin | F26: =F25/F6 -> 0.23416532 | G26: =G25/G6 -> 0.2258983 | H26: =H25/H6 -> 0.27339855
B28: Diluted EPS | F28: =F25/F29 -> 2.4692325 | G28: =G25/G29 -> 2.4608796 | H28: =H25/H29 -> 3.038952
B29: Diluted shares outstanding | F29: 4339 | G29: 4320 | H29: 4313
B31: Memo: As reported
B32: Gross profit (reported) | F32: 27234 | G32: 28737 | H32: 29544
B33: Operating income (reported) | F33: 11311 | G33: 9992 | H33: 13762
B34: Pre-tax income (reported) | F34: 12952 | G34: 13086 | H34: 15998
B35: Consolidated net income (reported) | F35: 10703 | G35: 10649 | H35: 13137
B36: Net income attributable to KO (reported) | F36: 10714 | G36: 10631 | H36: 13107
B37: Diluted EPS (reported) | F37: 2.47 | G37: 2.46 | H37: 3.04
B39: Checks (should be zero)
B40: Gross profit | F40: =F9-F32 -> 0 | G40: =G9-G32 -> 0 | H40: =H9-H32 -> 0
B41: Operating income | F41: =F14-F33 -> 0 | G41: =G14-G33 -> 0 | H41: =H14-H33 -> 0
B42: Pre-tax income | F42: =F20-F34 -> 0 | G42: =G20-G34 -> 0 | H42: =H20-H34 -> 0
B43: Consolidated net income | F43: =F23-F35 -> 0 | G43: =G23-G35 -> 0 | H43: =H23-H35 -> 0
B44: Net income attributable to KO | F44: =F25-F36 -> 0 | G44: =G25-G36 -> 0 | H44: =H25-H36 -> 0
...

Sheet CF
B1: The Coca-Cola Company (NYSE: KO)
B2: Cash Flow Statement
B3: ($ in millions)
B5: Fiscal Year Ending December 31, | D5: 2021 | E5: =D5+1 -> 2022 | F5: =E5+1 -> 2023 | G5: =F5+1 -> 2024 | H5: =G5+1 -> 2025
B6: Consolidated Net Income | F6: 10703 | G6: 10649 | H6: 13137
B7: Depreciation and amortization | F7: 1128 | G7: 1075 | H7: 1050
B8: Stock-based compensation expense | F8: 254 | G8: 286 | H8: 279
B9: Deferred income taxes | F9: -2 | G9: -11 | H9: 517
B10: Equity (income) loss — net of dividends | F10: -1019 | G10: -802 | H10: -1038
B11: Foreign currency adjustments | F11: 175 | G11: -110 | H11: 191
B12: Significant (gains) losses — net | F12: -492 | G12: -1737 | H12: -713
B13: Other operating charges | F13: 1741 | G13: 4000 | H13: 1052
B14: Other items | F14: -43 | G14: -311 | H14: 141
B15: Net change in operating assets and liabilities | F15: -846 | G15: -6234 | H15: -7208
B16: Cash flow from operations | F16: =SUM(F6:F15) -> 11599 | G16: =SUM(G6:G15) -> 6805 | H16: =SUM(H6:H15) -> 7408
B17: Capital expenditures | F17: -1852 | G17: -2064 | H17: -2112
B18: Free cash flow | F18: =F16+F17 -> 9747 | G18: =G16+G17 -> 4741 | H18: =H16+H17 -> 5296
B19: Plus: IRS tax litigation deposit | C19: FY25 10-K p.53 | F19: 0 | G19: 6000 | H19: 0
B20: Plus: fairlife contingent payment | C20: FY25 10-K p.53 | F20: 0 | G20: 0 | H20: 6100
B21: Adjusted free cash flow | F21: =F18+F19+F20 -> 9747 | G21: =G18+G19+G20 -> 10741 | H21: =H18+H19+H20 -> 11396
B22: Adj. FCF % of revenue | F22: =F21/IS!F6 -> 0.21303055 | G22: =G21/IS!G6 -> 0.22823569 | H22: =H21/IS!H6 -> 0.23770885
B24: D&A % of revenue | F24: =F7/IS!F6 -> 0.024653582 | G24: =G7/IS!G6 -> 0.022842694 | H24: =H7/IS!H6 -> 0.021901921
B25: CapEx % of revenue | F25: =-F17/IS!F6 -> 0.040477335 | G25: =-G17/IS!G6 -> 0.043857972 | H25: =-H17/IS!H6 -> 0.04405415
B26: CapEx / D&A | F26: =-F17/F7 -> 1.641844 | G26: =-G17/G7 -> 1.92 | H26: =-H17/H7 -> 2.0114286
B28: Memo: As reported
B29: Net Cash Provided by Operating Activities | F29: 11599 | G29: 6805 | H29: 7408
B31: Checks (should be zero)
B32: Net Cash Provided by Operating Activities | F32: =F16-F29 -> 0 | G32: =G16-G29 -> 0 | H32: =H16-H29 -> 0

Sheet BS
B1: The Coca-Cola Company (NYSE: KO)
B2: Balance Sheet
B3: ($ in millions)
B5: Fiscal Year Ending December 31, | D5: 2021 | E5: =D5+1 -> 2022 | F5: =E5+1 -> 2023 | G5: =F5+1 -> 2024 | H5: =G5+1 -> 2025
B6: CURRENT ASSETS
B7: Cash and cash equivalents | F7: 9366 | G7: 10828 | H7: 10270
B8: Short-term investments | F8: 2997 | G8: 2020 | H8: 3602
B9: Total Cash, Cash Equivalents and Short-Term Investments | F9: =SUM(F7:F8) -> 12363 | G9: =SUM(G7:G8) -> 12848 | H9: =SUM(H7:H8) -> 13872
B10: Marketable securities | F10: 1300 | G10: 1723 | H10: 1934
B11: Accounts receivable, net | F11: 3410 | G11: 3569 | H11: 3038
B12: Inventories | F12: 4424 | G12: 4728 | H12: 4425
B13: Prepaid expenses and other current assets | F13: 5235 | G13: 2998 | H13: 2433
B14: Assets held for sale | F14: 0 | G14: 131 | H14: 5342
B15: Total Current Assets | F15: =SUM(F9:F14) -> 26732 | G15: =SUM(G9:G14) -> 25997 | H15: =SUM(H9:H14) -> 31044
B16: Equity method investments | F16: 19671 | G16: 18087 | H16: 20235
B17: Deferred income tax assets | F17: 1561 | G17: 1319 | H17: 1206
B18: PP&E, net | F18: 9236 | G18: 10303 | H18: 9613
B19: Trademarks with indefinite lives | F19: 14349 | G19: 13301 | H19: 12531
B20: Goodwill | F20: 18358 | G20: 18139 | H20: 15491
B21: Other noncurrent assets | F21: 7796 | G21: 13403 | H21: 14696
B22: Total Assets | F22: =SUM(F15:F21) -> 97703 | G22: =SUM(G15:G21) -> 100549 | H22: =SUM(H15:H21) -> 104816
B23: CURRENT LIABILITIES
B24: Accounts payable and accrued expenses | F24: 15485 | G24: 21712 | H24: 14813
B25: Loans and notes payable | F25: 4557 | G25: 1499 | H25: 1551
B26: Current maturities of long-term debt | F26: 1960 | G26: 648 | H26: 1822
B27: Accrued income taxes | F27: 1569 | G27: 1387 | H27: 525
B28: Liabilities held for sale | F28: 0 | G28: 3 | H28: 2570
B29: Total Current Liabilities | F29: =SUM(F24:F28) -> 23571 | G29: =SUM(G24:G28) -> 25249 | H29: =SUM(H24:H28) -> 21281
B30: Long-term debt | F30: 35547 | G30: 42375 | H30: 42119
B31: Other noncurrent liabilities | F31: 8466 | G31: 4084 | H31: 4735
B32: Deferred income tax liabilities | F32: 2639 | G32: 2469 | H32: 2406
B33: Total liabilities | F33: =SUM(F29:F32) -> 70223 | G33: =SUM(G29:G32) -> 74177 | H33: =SUM(H29:H32) -> 70541
B34: SHAREOWNERS' EQUITY
B35: Common stock | F35: 1760 | G35: 1760 | H35: 1760
B36: Capital surplus | F36: 19209 | G36: 19801 | H36: 20581
B37: Reinvested earnings | F37: 73782 | G37: 76054 | H37: 80382
B38: Accumulated other comprehensive income (loss) | F38: -14275 | G38: -16843 | H38: -14131
B39: Treasury stock | F39: -54535 | G39: -55916 | H39: -56423
B40: Equity attributable to KO shareowners | F40: =SUM(F35:F39) -> 25941 | G40: =SUM(G35:G39) -> 24856 | H40: =SUM(H35:H39) -> 32169
B41: Noncontrolling interests (NCI) | F41: 1539 | G41: 1516 | H41: 2106
...

Sheet NWC
B1: The Coca-Cola Company (NYSE: KO)
B2: Net Working Capital
B3: ($ in millions)
B5: Fiscal Year Ending December 31, | D5: 2021 | E5: =D5+1 -> 2022 | F5: =E5+1 -> 2023 | G5: =F5+1 -> 2024 | H5: =G5+1 -> 2025
B6: Accounts receivable, net | F6: =BS!F11 -> 3410 | G6: =BS!G11 -> 3569 | H6: =BS!H11 -> 3038
B7: Inventories | F7: =BS!F12 -> 4424 | G7: =BS!G12 -> 4728 | H7: =BS!H12 -> 4425
B8: Prepaid expenses and other current assets | F8: =BS!F13 -> 5235 | G8: =BS!G13 -> 2998 | H8: =BS!H13 -> 2433
B9: Less: Accounts payable and accrued expenses | F9: =BS!F24 -> 15485 | G9: =BS!G24 -> 21712 | H9: =BS!H24 -> 14813
B10: Plus: fairlife contingent consideration liability | C10: FY25 10-K, Note 8, p. 86 | F10: 0 | G10: 6126 | H10: 0
B11: Adj. Net working capital | F11: =SUM(F6:F8)-F9+F10 -> -2416 | G11: =SUM(G6:G8)-G9+G10 -> -4291 | H11: =SUM(H6:H8)-H9+H10 -> -4917
B12: % of revenue | F12: =F11/IS!F6 -> -0.052804126 | G12: =G11/IS!G6 -> -0.091179533 | H12: =H11/IS!H6 -> -0.10256357
B13: (Increase)/decrease in NWC | G13: =F11-G11 -> 1875 | H13: =G11-H11 -> 626
B15: Working capital metrics
B16: DSO (days) | F16: =F6/IS!F6*365 -> 27.203086 | G16: =G6/IS!G6*365 -> 27.680776 | H16: =H6/IS!H6*365 -> 23.129889
B17: DIO (days) | F17: =F7/IS!F8*365 -> 87.190065 | G17: =G7/IS!G8*365 -> 94.178127 | H17: =H7/IS!H8*365 -> 87.792847
B18: DPO (days) | F18: =(F9-F10)/IS!F8*365 -> 305.18494 | G18: =(G9-G10)/IS!G8*365 -> 310.46114 | H18: =(H9-H10)/IS!H8*365 -> 293.89275
B19: Prepaid % of revenue | F19: =F8/IS!F6 -> 0.11441623 | G19: =G8/IS!G6 -> 0.063704554 | H19: =H8/IS!H6 -> 0.05074988
B20: Cash conversion cycle (days) | F20: =F16+F17-F18 -> -190.79178 | G20: =G16+G17-G18 -> -188.60224 | H20: =H16+H17-H18 -> -182.97002
B22: Checks (should be zero)
B23: Adj. Net working capital (vs. BS) | F23: =F11-(BS!F11+BS!F12+BS!F13-BS!F24+F10) -> 0 | G23: =G11-(BS!G11+BS!G12+BS!G13-BS!G24+G10) -> 0 | H23: =H11-(BS!H11+BS!H12+BS!H13-BS!H24+H10) -> 0

Sheet Adj
B1: The Coca-Cola Company (NYSE: KO)
B2: Adj EBIT/EBITDA
B3: ($ in millions)
B5: Fiscal Year Ending December 31, | D5: 2021 | E5: =D5+1 -> 2022 | F5: =E5+1 -> 2023 | G5: =F5+1 -> 2024 | H5: =G5+1 -> 2025
B6: Operating income | F6: =IS!F14 -> 11311 | G6: =IS!G14 -> 9992 | H6: =IS!H14 -> 13762
B7: Plus: Other operating charges | F7: =IS!F13 -> 1951 | G7: =IS!G13 -> 4163 | H7: =IS!H13 -> 1261
B8: Adjusted EBIT | F8: =SUM(F6:F7) -> 13262 | G8: =SUM(G6:G7) -> 14155 | H8: =SUM(H6:H7) -> 15023
B9: % margin | F9: =F8/IS!F6 -> 0.28985444 | G9: =G8/IS!G6 -> 0.30077984 | H9: =H8/IS!H6 -> 0.31336434
B10: Plus: D&A | F10: =CF!F7 -> 1128 | G10: =CF!G7 -> 1075 | H10: =CF!H7 -> 1050
B11: Adjusted EBITDA | F11: =F8+F10 -> 14390 | G11: =G8+G10 -> 15230 | H11: =H8+H10 -> 16073
B12: % margin | F12: =F11/IS!F6 -> 0.31450802 | G12: =G11/IS!G6 -> 0.32362253 | H12: =H11/IS!H6 -> 0.33526626
B14: Memo: Company-reported
B15: Comparable operating margin (non-GAAP) | C15: Q4'24 & Q4'25 earnings releases | F15: 0.291 | G15: 0.3 | H15: 0.312
B16: Difference vs. Adjusted EBIT margin | F16: =F9-F15 -> -0.001145561 | G16: =G9-G15 -> 0.00077983893 | H16: =H9-H15 -> 0.0013643437

Sheet WACC
B1: The Coca-Cola Company (NYSE: KO)
B2: Weighted Average Cost of Capital
B3: ($ in millions, except per share data; as of September 30, 2026)
B5: Cost of Equity | C5: Source | D5: Input
B6: Risk-free rate | C6: U.S. Treasury 10-Year par yield as of 09/30/2026 (treasury.gov, Daily Treasury Par Yield Curve Rates) | D6: 0.0529
B7: Unlevered beta (comps median, Blume-adjusted) | C7: Comps median (row 38) | D7: =J38 -> 0.49457117
B8: Debt / equity (market value) | C8: Capital structure (row 27) | D8: =D27 -> 0.11728342
B9: Tax rate | C9: DCF!I13 | D9: =DCF!I13 -> 0.2
B10: Levered beta | C10: Hamada: βL = βU × [1 + (1 − t) × D/E] | D10: =D7*(1+(1-D9)*D8) -> 0.54097517
B11: Equity risk premium | C11: Kroll recommended U.S. ERP (5.0%) | D11: 0.05
B12: Cost of equity | C12: CAPM | D12: =D6+D10*D11 -> 0.079948758
B14: Cost of Debt
B15: Pre-tax cost of debt | C15: ICE BofA Single-A US Corp. Index Effective Yield, 9/30/26 (FRED: BAMLC0A3CAEY); KO rated A+/A1 | D15: 0.0588
B16: Tax rate | D16: =D9 -> 0.2
B17: After-tax cost of debt | D17: =D15*(1-D16) -> 0.04704
B19: Capital Structure
B20: Share price (9/30/26) | C20: Stock Analysis historical prices, close 9/30/2026 | D20: 86.08
B21: Diluted shares outstanding (mm) | C21: Q2'26 10-Q: diluted wtd. avg. shares, 3M ended 7/3/26 | D21: 4313
B22: Market value of equity | D22: =D20*D21 -> 371263.04
B23: Total debt | C23: Q2'26 10-Q balance sheet (7/3/26), see comment | D23: 43543
B24: Total capitalization | D24: =D23+D22 -> 414806.04
B25: Debt / total capitalization | D25: =D23/D24 -> 0.10497195
B26: Equity / total capitalization | D26: =D22/D24 -> 0.89502805
B27: Debt / equity | D27: =D23/D22 -> 0.11728342
B29: WACC | D29: =D12*D26+D17*D25 -> 0.076494262
B31: Blume weight on raw beta | E31: 0.67
B32: Company | C32: Ticker | D32: Levered beta | E32: Adjusted beta | F32: Equity value | G32: Total debt | H32: D/E | I32: Tax rate | J32: Unlevered beta
B33: PepsiCo | C33: PEP | D33: 0.36 | E33: =$E$31*D33+(1-$E$31) -> 0.5712 | F33: 172961 | G33: 53214 | H33: =G33/F33 -> 0.30766473 | I33: 0.21 | J33: =E33/(1+(1-I33)*H33) -> 0.459513
B34: Keurig Dr Pepper | C34: KDP | D34: 0.41 | E34: =$E$31*D34+(1-$E$31) -> 0.6047 | F34: 41290 | G34: 34480 | H34: =G34/F34 -> 0.83506902 | I34: 0.21 | J34: =E34/(1+(1-I34)*H34) -> 0.36434196
B35: Monster Beverage | C35: MNST | D35: 0.49 | E35: =$E$31*D35+(1-$E$31) -> 0.6583 | F35: 81537 | G35: 93 | H35: =G35/F35 -> 0.0011405865 | I35: 0.21 | J35: =E35/(1+(1-I35)*H35) -> 0.65770736
B36: Coca-Cola Europacific Partners | C36: CCEP | D36: 0.48 | E36: =$E$31*D36+(1-$E$31) -> 0.6516 | F36: 45076 | G36: 13841 | H36: =G36/F36 -> 0.30705919 | I36: 0.25 | J36: =E36/(1+(1-I36)*H36) -> 0.52962933
B37: Mean | D37: =AVERAGE(D33:D36) -> 0.435 | E37: =AVERAGE(E33:E36) -> 0.62145 | H37: =AVERAGE(H33:H36) -> 0.36273338 | J37: =AVERAGE(J33:J36) -> 0.50279792
B38: Median | D38: =MEDIAN(D33:D36) -> 0.445 | E38: =MEDIAN(E33:E36) -> 0.62815 | H38: =MEDIAN(H33:H36) -> 0.30736196 | J38: =MEDIAN(J33:J36) -> 0.49457117
B40: The Coca-Cola Company (reference only) | C40: KO | D40: 0.32 | E40: =$E$31*D40+(1-$E$31) -> 0.5444 | F40: =D22 -> 371263.04 | G40: =D23 -> 43543 | H40: =G40/F40 -> 0.11728342 | I40: =D9 -> 0.2 | J40: =E40/(1+(1-I40)*H40) -> 0.49770222
B42: Notes
B43: (1) Levered beta: 5-year beta vs. S&P 500 per Stock Analysis (stockanalysis.com), accessed 10/7/2026; raw (unadjusted).
B44: (2) Equity value: 9/30/2026 closing price x latest shares outstanding (Stock Analysis); see cell comments.
B45: (3) Total debt: latest reported quarter per Stock Analysis (may include lease liabilities). CCEP figures in USD.
B46: (4) Tax rate: statutory rate (U.S. federal 21%; U.K. 25% for CCEP).
B47: (5) KO shown for reference only; excluded from mean/median. KDP leverage elevated following JDE Peet's acquisition.
...

Sheet CCBA
B1: The Coca-Cola Company (NYSE: KO)
B2: CCBA Deconsolidation – Pro Forma Analysis
B3: ($ in millions, unless otherwise noted)
B5: A. Bottling Investments segment (FY2025A)
B6: Net operating revenues | D6: 5735
B7: Operating income | D7: 426
B8: Operating margin % | D8: =D7/D6 -> 0.074280732
B9: D&A | D9: 313
B10: D&A % of revenue | D10: =D9/D6 -> 0.054577158
B11: CapEx | D11: 547
B12: CapEx % of revenue | D12: =D11/D6 -> 0.09537925
B14: B. CCBA size estimate
B15: KO net operating revenues | D15: =IS!H6 -> 47941
B16: Less: Bottling Investments revenue | D16: =-D6 -> -5735
B17: KO revenue ex-Bottling Investments | D17: =D15+D16 -> 42206
B18: Bottling Investments % of post-deal revenue | D18: 0.05
B19: Implied remaining Bottling Investments revenue | D19: =D17*D18/(1-D18) -> 2221.3684
B20: Implied CCBA revenue | D20: =D6-D19 -> 3513.6316
B21: % of KO revenue | D21: =D20/D15 -> 0.073290744
B22: Implied CCBA operating income | D22: =D20*D8 -> 260.99513
B23: Implied CCBA D&A | D23: =D20*D10 -> 191.76403
B24: Implied CCBA CapEx | D24: =D20*D12 -> 335.12755
B27: C. Pro forma FY2025A (ex-CCBA) | D27: Reported | E27: Less: CCBA | F27: Pro Forma | G27: Δ
B28: Net operating revenues | D28: =IS!H6 -> 47941 | E28: =-D20 -> -3513.6316 | F28: =D28+E28 -> 44427.368
B29: Adjusted EBIT | D29: =Adj!H8 -> 15023 | E29: =-D22 -> -260.99513 | F29: =D29+E29 -> 14762.005
B30: % margin | D30: =D29/D28 -> 0.31336434 | E30: =E29/E28 -> 0.074280732 | F30: =F29/F28 -> 0.33227277 | G30: =F30-D30 -> 0.018908429
B31: D&A | D31: =CF!H7 -> 1050 | E31: =-D23 -> -191.76403 | F31: =D31+E31 -> 858.23597
B32: % of revenues | D32: =D31/D28 -> 0.021901921 | E32: =E31/E28 -> 0.054577158 | F32: =F31/F28 -> 0.019317732 | G32: =F32-D32 -> -0.0025841896
B33: Adjusted EBITDA | D33: =D29+D31 -> 16073 | E33: =E29+E31 -> -452.75915 | F33: =F29+F31 -> 15620.241
B34: % margin | D34: =D33/D28 -> 0.33526626 | E34: =E33/E28 -> 0.12885789 | F34: =F33/F28 -> 0.3515905 | G34: =F34-D34 -> 0.016324239
B35: Capital expenditures | D35: =-CF!H17 -> 2112 | E35: =-D24 -> -335.12755 | F35: =D35+E35 -> 1776.8725
B36: % of revenues | D36: =D35/D28 -> 0.04405415 | E36: =E35/E28 -> 0.09537925 | F36: =F35/F28 -> 0.039994997 | G36: =F36-D36 -> -0.0040591532
B38: Check: Adj. EBITDA vs. Adj tab | D38: =D33-Adj!H11 -> 0
B39: Check: Bottling Inv. % of post-deal revenue | D39: =D19/F28-D18 -> 0
B41: D. FY2027E Revenue Impact
B42: CCBA revenue FY2025A | D42: =D20 -> 3513.6316
B43: CCBA growth FY2026E (organic + FX) | D43: =DCF!I8+DCF!I9 -> 0.06
B44: CCBA revenue FY2026E | D44: =D42*(1+D43) -> 3724.4495
B45: KO revenue FY2026E | D45: =DCF!I19 -> 49618.935
B46: FY2027E structural impact | D46: =-D44/D45 -> -0.075061052
...

Sheet EMI
B1: The Coca-Cola Company (NYSE: KO)
B2: Equity Method Investments – Listed Stakes at Market Value
B3: ($ in millions)
B5: Company | C5: Ticker | D5: KO ownership | E5: Market cap | F5: KO stake value | G5: Carrying value (12/31/25) | H5: Source
B6: Monster Beverage | C6: MNST | D6: 0.21 | E6: 81537 | F6: =D6*E6 -> 17122.77 | G6: 5593 | H6: 9/30/26 close $41.62 × 1,959.1mm sh. (Stock Analysis)
B7: Coca-Cola Europacific Partners | C7: CCEP | D7: 0.18 | E7: 45076 | F7: =D7*E7 -> 8113.68 | G7: 3926 | H7: 9/30/26 close $101.71 × 443.18mm sh. (Stock Analysis)
B8: Coca-Cola FEMSA | C8: KOF | D8: 0.28 | E8: 22697 | F8: =D8*E8 -> 6355.16 | G8: 2236 | H8: 9/30/26 ADS close $108.04 × 210.08mm ADS (Stock Analysis)
B9: Coca-Cola HBC | C9: LON:CCH | D9: 0.22 | E9: 21053 | F9: =D9*E9 -> 4631.66 | G9: 1391 | H9: 9/30/26 close 4,354p × 364.46mm sh. × 1.3267 USD/GBP (FRED)
B10: Coca-Cola Bottlers Japan | C10: TYO:2579 | D10: 0.24 | E10: 3847 | F10: =D10*E10 -> 923.28 | G10: 459 | H10: 10/8/26 mkt cap ¥604.93bn ÷ 157.25 JPY/USD (9/30, FRED)
B11: Coca-Cola İçecek | C11: IST:CCOLA | D11: n.a. | E11: n.a. | F11: 770 | G11: 288 | H11: Fair value 12/31/25 per KO FY25 10-K
B12: Embotelladora Andina | C12: SNSE:ANDINA | D12: n.a. | E12: n.a. | F12: 278 | G12: 106 | H12: Fair value 12/31/25 per KO FY25 10-K
B13: Total listed stakes | F13: =SUM(F6:F12) -> 38194.55 | G13: =SUM(G6:G12) -> 13999
B14: Carrying value per 10-K (12/31/25) | G14: 13999
B15: Check (should be zero) | G15: =G13-G14 -> 0
B17: Adjusted Equity Method Investments
B18: Equity method investments, book value (7/3/26) | F18: 20782 | H18: Q2'26 10-Q balance sheet
B19: Less: Carrying value of listed stakes | F19: =-G13 -> -13999
B20: Unlisted / other equity method investments (book value) | F20: =F18+F19 -> 6783
B21: Plus: Market value of listed stakes | F21: =F13 -> 38194.55
B22: Equity method investments, adjusted | F22: =F20+F21 -> 44977.55
B24: Notes
B25: (1) Ownership per KO FY2025 10-K (Equity Method Investments note). Market values as of 9/30/2026 valuation date unless noted.
B26: (2) Coca-Cola İçecek and Embotelladora Andina at 12/31/25 fair value per 10-K (immaterial; not rolled forward).
B27: (3) Carrying values of listed stakes are 12/31/25 (latest disclosed); total book value is 7/3/26. Unlisted stakes (e.g., AC Bebidas) kept at book value.
B28: (4) No tax on unrealized gains or minority discount applied.

Sheet DCF
B1: The Coca-Cola Company (NYSE: KO)
B2: Discounted Cash Flow Analysis
B3: ($ in millions, except per share data)
D4: Historical | I4: Projected
D5: =IS!D5 -> 2021 | E5: =D5+1 -> 2022 | F5: =E5+1 -> 2023 | G5: =F5+1 -> 2024 | H5: =G5+1 -> 2025 | I5: =H5+1 -> 2026 | J5: =I5+1 -> 2027 | K5: =J5+1 -> 2028 | L5: =K5+1 -> 2029 | M5: =L5+1 -> 2030
B7: Key assumptions
B8: Organic growth % | C8: Q4'24 & Q4'25 earnings releases | G8: 0.12 | H8: 0.05 | I8: 0.05 | J8: 0.045 | K8: 0.045 | L8: 0.04 | M8: 0.03
B9: FX impact % | C9: Q4'24 & Q4'25 earnings releases | G9: -0.05 | H9: -0.02 | I9: 0.01 | J9: 0 | K9: 0 | L9: 0 | M9: 0
B10: Acquisitions/Divestitures % | C10: Q4'24 & Q4'25 earnings releases | G10: -0.04 | H10: -0.01 | I10: -0.025 | J10: =CCBA!D46 -> -0.075061052 | K10: 0 | L10: 0 | M10: 0
B11: Revenue growth % | G11: =G19/F19-1 -> 0.028565808 | H11: =H19/G19-1 -> 0.018699135 | I11: =SUM(I8:I10) -> 0.035 | J11: =SUM(J8:J10) -> -0.030061052 | K11: =SUM(K8:K10) -> 0.045 | L11: =SUM(L8:L10) -> 0.04 | M11: =SUM(M8:M10) -> 0.03
B12: Adjusted EBIT margin % | F12: =F20/F19 -> 0.28985444 | G12: =G20/G19 -> 0.30077984 | H12: =H20/H19 -> 0.31336434 | I12: 0.315 | J12: 0.335 | K12: 0.337 | L12: 0.338 | M12: 0.338
B13: Tax rate % | C13: Q2'26 release: ETR 19.9% | F13: =IS!F22 -> 0.17364114 | G13: =IS!G22 -> 0.18622956 | H13: =IS!H22 -> 0.17883485 | I13: 0.2 | J13: 0.2 | K13: 0.2 | L13: 0.2 | M13: 0.2
B14: D&A % of revenue | F14: =F23/F19 -> 0.024653582 | G14: =G23/G19 -> 0.022842694 | H14: =H23/H19 -> 0.021901921 | I14: 0.022 | J14: 0.02 | K14: 0.02 | L14: 0.02 | M14: 0.02
B15: CapEx % of revenue | F15: =-F24/F19 -> 0.040477335 | G15: =-G24/G19 -> 0.043857972 | H15: =-H24/H19 -> 0.04405415 | I15: 0.044 | J15: 0.039 | K15: 0.038 | L15: 0.037 | M15: 0.036
B16: Adj. NWC % of revenue | F16: =F28/F19 -> -0.052804126 | G16: =G28/G19 -> -0.091179533 | H16: =H28/H19 -> -0.10256357 | I16: -0.1 | J16: -0.1 | K16: -0.1 | L16: -0.1 | M16: -0.1
B18: Unlevered free cash flow
B19: Revenue | F19: =IS!F6 -> 45754 | G19: =IS!G6 -> 47061 | H19: =IS!H6 -> 47941 | I19: =H19*(1+I11) -> 49618.935 | J19: =I19*(1+J11) -> 48127.338 | K19: =J19*(1+K11) -> 50293.068 | L19: =K19*(1+L11) -> 52304.791 | M19: =L19*(1+M11) -> 53873.934
B20: Adjusted EBIT | F20: =Adj!F8 -> 13262 | G20: =Adj!G8 -> 14155 | H20: =Adj!H8 -> 15023 | I20: =I12*I19 -> 15629.965 | J20: =J12*J19 -> 16122.658 | K20: =K12*K19 -> 16948.764 | L20: =L12*L19 -> 17679.019 | M20: =M12*M19 -> 18209.39
B21: Less: Taxes | F21: =-F13*F20 -> -2302.8288 | G21: =-G13*G20 -> -2636.0794 | H21: =-H13*H20 -> -2686.636 | I21: =-I20*I13 -> -3125.9929 | J21: =-J20*J13 -> -3224.5316 | K21: =-K20*K13 -> -3389.7528 | L21: =-L20*L13 -> -3535.8038 | M21: =-M20*M13 -> -3641.878
B22: NOPAT | F22: =F20+F21 -> 10959.171 | G22: =G20+G21 -> 11518.921 | H22: =H20+H21 -> 12336.364 | I22: =I20+I21 -> 12503.972 | J22: =J20+J21 -> 12898.126 | K22: =K20+K21 -> 13559.011 | L22: =L20+L21 -> 14143.215 | M22: =M20+M21 -> 14567.512
B23: Plus: D&A | F23: =CF!F7 -> 1128 | G23: =CF!G7 -> 1075 | H23: =CF!H7 -> 1050 | I23: =I19*I14 -> 1091.6166 | J23: =J19*J14 -> 962.54675 | K23: =K19*K14 -> 1005.8614 | L23: =L19*L14 -> 1046.0958 | M23: =M19*M14 -> 1077.4787
B24: Less: CapEx | F24: =CF!F17 -> -1852 | G24: =CF!G17 -> -2064 | H24: =CF!H17 -> -2112 | I24: =-I19*I15 -> -2183.2331 | J24: =-J19*J15 -> -1876.9662 | K24: =-K19*K15 -> -1911.1366 | L24: =-L19*L15 -> -1935.2772 | M24: =-M19*M15 -> -1939.4616
B25: (Increase)/Decrease in NWC | G25: =NWC!G13 -> 1875 | H25: =NWC!H13 -> 626 | I25: =H28-I28 -> 44.8935 | J25: =I28-J28 -> -149.15974 | K25: =J28-K28 -> 216.57302 | L25: =K28-L28 -> 201.17227 | M25: =L28-M28 -> 156.91437
B26: Unlevered free cash flow | G26: =SUM(G22:G25) -> 12404.921 | H26: =SUM(H22:H25) -> 11900.364 | I26: =SUM(I22:I25) -> 11457.249 | J26: =SUM(J22:J25) -> 11834.547 | K26: =SUM(K22:K25) -> 12870.309 | L26: =SUM(L22:L25) -> 13455.206 | M26: =SUM(M22:M25) -> 13862.443
B28: Memo: Adj. Net working capital | F28: =NWC!F11 -> -2416 | G28: =NWC!G11 -> -4291 | H28: =NWC!H11 -> -4917 | I28: =I16*I19 -> -4961.8935 | J28: =J16*J19 -> -4812.7338 | K28: =K16*K19 -> -5029.3068 | L28: =L16*L19 -> -5230.4791 | M28: =M16*M19 -> -5387.3934
B29: Memo: Adj. EBITDA | F29: =F20+F23 -> 14390 | G29: =G20+G23 -> 15230 | H29: =H20+H23 -> 16073 | I29: =I20+I23 -> 16721.581 | J29: =J20+J23 -> 17085.205 | K29: =K20+K23 -> 17954.625 | L29: =L20+L23 -> 18725.115 | M29: =M20+M23 -> 19286.868
B31: Terminal Value
B32: Perpetuity Growth Method
B33: Terminal year UFCF (FY2030E) | D33: =M26 -> 13862.443
B34: Perpetuity growth rate | C34: ≤ long-term nominal GDP; < Rf (5.29%); = FY30E organic growth | D34: 0.03
B35: WACC | C35: WACC tab (rounded to 0.01%) | D35: =ROUND(WACC!D29,4) -> 0.0765
B36: Terminal value | D36: =D33*(1+D34)/(D35-D34) -> 307060.57
B37: Implied EV / LTM EBITDA | D37: =D36/M29 -> 15.920706
B38: Implied EV / NTM EBITDA | D38: =D36/(M29*(1+D34)) -> 15.456997
B40: Exit Multiple Method
B41: Terminal year Adj. EBITDA (FY2030E) | D41: =M29 -> 19286.868
B42: Exit multiple (EV / LTM EBITDA) | C42: Premium to comps median (12.6x), discount to KO current (23.5x) given maturity by FY30E | D42: 18
B43: Terminal value | D43: =D41*D42 -> 347163.63
B44: Implied perpetuity growth rate | D44: =(D43*D35-D33)/(D43+D33) -> 0.035165257
B46: Exit multiple reference: EV / LTM EBITDA | C46: Comp tab (LTM adj. EBITDA, 9/30/26 prices)
...

Sheet Comp
B1: The Coca-Cola Company (NYSE: KO)
B2: Trading Comparables
B3: ($ in millions, except per share data; market data as of September 30, 2026)
B5: Company | D5: PepsiCo | E5: Keurig Dr Pepper | F5: Monster Beverage | G5: CCEP
B6: Ticker | D6: PEP | E6: KDP | F6: MNST | G6: CCEP
B7: Reporting currency | D7: USD | E7: USD | F7: USD | G7: EUR
B8: Latest balance sheet date | D8: 46186 | E8: 46203 | F8: 46203 | G8: 46206
B9: FX rate (USD per local currency, 9/30/26) | D9: 1 | E9: 1 | F9: 1 | G9: 1.1355
B11: Enterprise Value
B12: Share price (9/30/26) | D12: 126.72 | E12: 30.34 | F12: 41.62 | G12: 101.71
B13: Equity value ($) | D13: =WACC!F33 -> 172961 | E13: =WACC!F34 -> 41290 | F13: =WACC!F35 -> 81537 | G13: =WACC!F36 -> 45076
B14: Plus: Total debt (local) | D14: =10602+42612 -> 53214 | E14: =8394+21586 -> 29980 | F14: 0 | G14: =1663+10526 -> 12189
B15: Plus: Preferred stock (local) | D15: 0 | E15: 4500 | F15: 0 | G15: 0
B16: Plus: Noncontrolling interest (local) | D16: 172 | E16: 4196 | F16: 0 | G16: 487
B17: Less: Cash & short-term investments (local) | D17: =-(10251+465) -> -10716 | E17: -1517 | F17: =-(2192.4+1226.8) -> -3419.2 | G17: =-(1753+241) -> -1994
B18: Enterprise value ($) | D18: =D13+D9*SUM(D14:D17) -> 215631 | E18: =E13+E9*SUM(E14:E17) -> 78449 | F18: =F13+F9*SUM(F14:F17) -> 78117.8 | G18: =G13+G9*SUM(G14:G17) -> 57205.411
B20: LTM Adjusted EBITDA (local currency)
B21: Adj. EBIT – FY2025 | D21: 14912 | E21: 4156 | F21: 2582.6 | G21: 2808
B22: Plus: Adj. EBIT – H1 2026 | D22: 7117 | E22: 2316 | F22: 1481.6 | G22: 1481
B23: Less: Adj. EBIT – H1 2025 | D23: 6700 | E23: 1875 | F23: 1251.3 | G23: 1390
B24: LTM Adj. EBIT | D24: =D21+D22-D23 -> 15329 | E24: =E21+E22-E23 -> 4597 | F24: =F21+F22-F23 -> 2812.9 | G24: =G21+G22-G23 -> 2899
B25: D&A – FY2025 | D25: 3451 | E25: =455+160 -> 615 | F25: 114.4 | G25: 923
B26: Plus: D&A – H1 2026 | D26: 1639 | E26: =322+82 -> 404 | F26: 58.2 | G26: 439
B27: Less: D&A – H1 2025 | D27: 1491 | E27: =217+63 -> 280 | F27: 52.4 | G27: 469
B28: LTM D&A | D28: =D25+D26-D27 -> 3599 | E28: =E25+E26-E27 -> 739 | F28: =F25+F26-F27 -> 120.2 | G28: =G25+G26-G27 -> 893
B29: Plus: Pro forma acquisition adjustment | D29: 0 | E29: =E32-(E24+E28) -> 1275 | F29: 0 | G29: 0
B30: LTM Adj. EBITDA (local) | D30: =D24+D28+D29 -> 18928 | E30: =E24+E28+E29 -> 6611 | F30: =F24+F28+F29 -> 2933.1 | G30: =G24+G28+G29 -> 3792
B31: LTM Adj. EBITDA ($) | D31: =D30*D9 -> 18928 | E31: =E30*E9 -> 6611 | F31: =F30*F9 -> 2933.1 | G31: =G30*G9 -> 4305.816
B32: Memo: KDP-reported pro forma LTM Adj. EBITDA | E32: 6611
B34: NTM EPS (consensus, adjusted)
B35: FY2026E EPS (local) | D35: 8.39 | E35: 2.3 | F35: 1.15 | G35: 4.49
B36: FY2027E EPS (local) | D36: 8.69 | E36: 2.52 | F36: 1.31 | G36: 4.89
B37: Weight on FY2026E (remaining fraction of FY26) | D37: =DCF!$I$57 -> 0.25205479 | E37: =DCF!$I$57 -> 0.25205479 | F37: =DCF!$I$57 -> 0.25205479 | G37: =DCF!$I$57 -> 0.25205479
B38: NTM EPS ($) | D38: =(D35*D37+D36*(1-D37))*D9 -> 8.6143836 | E38: =(E35*E37+E36*(1-E37))*E9 -> 2.4645479 | F38: =(F35*F37+F36*(1-F37))*F9 -> 1.2696712 | G38: =(G35*G37+G36*(1-G37))*G9 -> 5.4381117
B40: Trading Multiples | I40: Max | J40: 75th pct | K40: Median | L40: 25th pct | M40: Min
B41: EV / LTM Adj. EBITDA | D41: =D18/D31 -> 11.39217 | E41: =E18/E31 -> 11.866435 | F41: =F18/F31 -> 26.633187 | G41: =G18/G31 -> 13.285614 | I41: =MAX(D41:G41) -> 26.633187 | J41: =_xlfn.QUARTILE.INC(D41:G41,3) -> 16.622507 | K41: =MEDIAN(D41:G41) -> 12.576025 | L41: =_xlfn.QUARTILE.INC(D41:G41,1) -> 11.747869 | M41: =MIN(D41:G41) -> 11.39217
B42: NTM P/E | D42: =D12/D38 -> 14.710281 | E42: =E12/E38 -> 12.310574 | F42: =F12/F38 -> 32.780139 | G42: =G12/G38 -> 18.703183 | I42: =MAX(D42:G42) -> 32.780139 | J42: =_xlfn.QUARTILE.INC(D42:G42,3) -> 22.222422 | K42: =MEDIAN(D42:G42) -> 16.706732 | L42: =_xlfn.QUARTILE.INC(D42:G42,1) -> 14.110354 | M42: =MIN(D42:G42) -> 12.310574
B45: Implied KO Share price
B46: KO LTM Adj. EBITDA
B47: Adj. EBIT - FY2025 | D47: =DCF!H20 -> 15023
...

Sheet Football Field
B1: The Coca-Cola Company (NYSE: KO)
B2: Valuation Summary – Football Field
B3: ($ per share)
B5: Methodology | C5: Assumption | D5: Low | E5: High | F5: Spread | H5: Price line X | I5: Y
B6: 52-week trading range | C6: Intraday, 10/1/25 - 9/30/26 | D6: =65.84 -> 65.84 | E6: 92.49 | F6: =E6-D6 -> 26.65 | H6: =$D$13 -> 86.08 | I6: 0
B7: Analyst price targets | C7: 24 analysts, as of 10/9/26 | D7: 75 | E7: 104 | F7: =E7-D7 -> 29 | H7: =$D$13 -> 86.08 | I7: 1
B8: Trading comps - EV / LTM EBITDA | C8: =TEXT(Comp!D77,"0.0x")&" - "&TEXT(Comp!E77,"0.0x") -> 13.0x - 17.0x | D8: =Comp!D78 -> 54.406775 | E8: =Comp!E78 -> 69.798605 | F8: =E8-D8 -> 15.39183
B9: Trading comps - NTM P/E | C9: =TEXT(Comp!D79,"0.0x")&" - "&TEXT(Comp!E79,"0.0x") -> 18.0x - 23.0x | D9: =Comp!D80 -> 62.361863 | E9: =Comp!E80 -> 79.684603 | F9: =E9-D9 -> 17.32274
B10: DCF - Perpetuity growth | C10: WACC 7.15%–8.15%; g 2.5%–3.5% | D10: =MIN(DCF!F104:H106) -> 58.602279 | E10: =MAX(DCF!F104:H106) -> 85.691946 | F10: =E10-D10 -> 27.089667
B11: DCF - Exit multiple | C11: WACC 7.15%–8.15%; 17.0x–19.0x | D11: =MIN(DCF!F115:H117) -> 69.626052 | E11: =MAX(DCF!F115:H117) -> 78.700586 | F11: =E11-D11 -> 9.0745335
B13: Current share price (9/30/26) | D13: =DCF!D84 -> 86.08
B47: Key takeaways:
B48: (1) Fundamental valuation (DCF $59–$86; comps $54–$80) sits below the current price of $86.08, which is supported only by the 52-week range and analyst targets.
B49: (2) The market is paying a premium for KO's brand, asset-light model and defensive cash flows (21.2x LTM EBITDA vs. peer median 12.6x) — implying a lower WACC or higher long-term growth than our base case.
B50: (3) On our assumptions, KO screens as fully valued; upside requires WACC ≤ ~7.2% with g ≥ 3.5%.
